[2023-09-15T02:04:39.564+0000] {taskinstance.py:1157} INFO - Dependencies all met for dep_context=non-requeueable deps ti=<TaskInstance: etl.executaCrawler manual__2023-09-15T01:58:52.848760+00:00 [queued]>
[2023-09-15T02:04:39.573+0000] {taskinstance.py:1157} INFO - Dependencies all met for dep_context=requeueable deps ti=<TaskInstance: etl.executaCrawler manual__2023-09-15T01:58:52.848760+00:00 [queued]>
[2023-09-15T02:04:39.573+0000] {taskinstance.py:1359} INFO - Starting attempt 3 of 3
[2023-09-15T02:04:39.588+0000] {taskinstance.py:1380} INFO - Executing <Task(_PythonDecoratedOperator): executaCrawler> on 2023-09-15 01:58:52.848760+00:00
[2023-09-15T02:04:39.592+0000] {standard_task_runner.py:57} INFO - Started process 190 to run task
[2023-09-15T02:04:39.596+0000] {standard_task_runner.py:84} INFO - Running: ['***', 'tasks', 'run', 'etl', 'executaCrawler', 'manual__2023-09-15T01:58:52.848760+00:00', '--job-id', '44', '--raw', '--subdir', 'DAGS_FOLDER/etl.py', '--cfg-path', '/tmp/tmpowhs1cna']
[2023-09-15T02:04:39.599+0000] {standard_task_runner.py:85} INFO - Job 44: Subtask executaCrawler
[2023-09-15T02:04:39.647+0000] {task_command.py:415} INFO - Running <TaskInstance: etl.executaCrawler manual__2023-09-15T01:58:52.848760+00:00 [running]> on host 25944728bab0
[2023-09-15T02:04:39.718+0000] {taskinstance.py:1660} INFO - Exporting env vars: AIRFLOW_CTX_DAG_OWNER='***' AIRFLOW_CTX_DAG_ID='etl' AIRFLOW_CTX_TASK_ID='executaCrawler' AIRFLOW_CTX_EXECUTION_DATE='2023-09-15T01:58:52.848760+00:00' AIRFLOW_CTX_TRY_NUMBER='3' AIRFLOW_CTX_DAG_RUN_ID='manual__2023-09-15T01:58:52.848760+00:00'
[2023-09-15T02:04:39.719+0000] {logging_mixin.py:151} INFO - Executando o crawler...
[2023-09-15T02:04:39.719+0000] {taskinstance.py:1935} ERROR - Task failed with exception
Traceback (most recent call last):
  File "/home/airflow/.local/lib/python3.8/site-packages/airflow/decorators/base.py", line 221, in execute
    return_value = super().execute(context)
  File "/home/airflow/.local/lib/python3.8/site-packages/airflow/operators/python.py", line 192, in execute
    return_value = self.execute_callable()
  File "/home/airflow/.local/lib/python3.8/site-packages/airflow/operators/python.py", line 209, in execute_callable
    return self.python_callable(*self.op_args, **self.op_kwargs)
  File "/opt/airflow/dags/etl.py", line 9, in executaCrawler
    main()
  File "/opt/airflow/dags/crawler.py", line 75, in main
    with open('./config.yaml') as f:
FileNotFoundError: [Errno 2] No such file or directory: './config.yaml'
[2023-09-15T02:04:39.726+0000] {taskinstance.py:1398} INFO - Marking task as FAILED. dag_id=etl, task_id=executaCrawler, execution_date=20230915T015852, start_date=20230915T020439, end_date=20230915T020439
[2023-09-15T02:04:39.739+0000] {standard_task_runner.py:104} ERROR - Failed to execute job 44 for task executaCrawler ([Errno 2] No such file or directory: './config.yaml'; 190)
[2023-09-15T02:04:39.768+0000] {local_task_job_runner.py:228} INFO - Task exited with return code 1
[2023-09-15T02:04:39.788+0000] {taskinstance.py:2776} INFO - 0 downstream tasks scheduled from follow-on schedule check
